Workbook

Sheet Pivot_Table
A1: Order_Status | B1: Completed
A2: Regional Analysis
A3: Row Labels | B3: Sum of Net_Sales
A4: Yorkshire | B4: 17988.95
A5: London | B5: 24315.2
A6: North West | B6: 24415.15
A7: South East | B7: 25871.55
A8: West Midlands | B8: 28616.3
A9: Grand Total | B9: 121207.15
A13: Order_Status | B13: Completed
A14: Product Category
A15: Row Labels | B15: Sum of Net_Sales | C15: Sum of Gross_profit
A16: Furniture | B16: 57384.75 | C16: 17888.75 | D16: =GETPIVOTDATA("Sum of Gross_profit",$A$15,"Product_Category",A16)/GETPIVOTDATA("Sum of Net_Sales",$A$15,"Product_Category",A16) -> 0.31173352
A17: Home Accessories | B17: 23189.4 | C17: 9274.4 | D17: =GETPIVOTDATA("Sum of Gross_profit",$A$15,"Product_Category",A17)/GETPIVOTDATA("Sum of Net_Sales",$A$15,"Product_Category",A17) -> 0.39994135
A18: Kitchenware | B18: 16850.5 | C18: 6227.5 | D18: =GETPIVOTDATA("Sum of Gross_profit",$A$15,"Product_Category",A18)/GETPIVOTDATA("Sum of Net_Sales",$A$15,"Product_Category",A18) -> 0.3695736
A19: Lighting | B19: 12222.75 | C19: 4703.75 | D19: =GETPIVOTDATA("Sum of Gross_profit",$A$15,"Product_Category",A19)/GETPIVOTDATA("Sum of Net_Sales",$A$15,"Product_Category",A19) -> 0.38483565
A20: Storage | B20: 11759.25 | C20: 4367.25 | D20: =GETPIVOTDATA("Sum of Gross_profit",$A$15,"Product_Category",A20)/GETPIVOTDATA("Sum of Net_Sales",$A$15,"Product_Category",A20) -> 0.37138848
A21: Grand Total | B21: 121406.65 | C21: 42461.65
A24: Order_Status | B24: Completed
A25: Category Sales Drivers
A26: Row Labels | B26: Sum of Quantity | C26: Sum of Gross_Sales | D26: Sum of Discount_Amt | E26: Sum of Net_Sales | F26: Sum of Total_Cost | G26: Sum of Gross_profit | I26: avg unit cost | J26: cost as % of net sales
A27: Home Accessories | B27: 265 | C27: 24899 | D27: 1709.6 | E27: 23189.4 | F27: 13915 | G27: 9274.4 | H27: =GETPIVOTDATA("Sum of Discount_Amt",$A$26,"Product_Category",A27)/GETPIVOTDATA("Sum of Gross_Sales",$A$26,"Product_Category",A27) -> 0.068661392 | I27: =GETPIVOTDATA("Sum of Total_Cost",$A$26,"Product_Category",A27)/GETPIVOTDATA("Sum of Quantity",$A$26,"Product_Category",A27) -> 52.509434 | J27: =GETPIVOTDATA("Sum of Total_Cost",$A$26,"Product_Category",A27)/GETPIVOTDATA("Sum of Net_Sales",$A$26,"Product_Category",A27) -> 0.60005865
A28: Furniture | B28: 253 | C28: 61500 | D28: 4115.25 | E28: 57384.75 | F28: 39496 | G28: 17888.75 | H28: =GETPIVOTDATA("Sum of Discount_Amt",$A$26,"Product_Category",A28)/GETPIVOTDATA("Sum of Gross_Sales",$A$26,"Product_Category",A28) -> 0.066914634 | I28: =GETPIVOTDATA("Sum of Total_Cost",$A$26,"Product_Category",A28)/GETPIVOTDATA("Sum of Quantity",$A$26,"Product_Category",A28) -> 156.11067 | J28: =GETPIVOTDATA("Sum of Total_Cost",$A$26,"Product_Category",A28)/GETPIVOTDATA("Sum of Net_Sales",$A$26,"Product_Category",A28) -> 0.68826648
A29: Kitchenware | B29: 245 | C29: 18353 | D29: 1502.5 | E29: 16850.5 | F29: 10623 | G29: 6227.5 | H29: =GETPIVOTDATA("Sum of Discount_Amt",$A$26,"Product_Category",A29)/GETPIVOTDATA("Sum of Gross_Sales",$A$26,"Product_Category",A29) -> 0.081866725 | I29: =GETPIVOTDATA("Sum of Total_Cost",$A$26,"Product_Category",A29)/GETPIVOTDATA("Sum of Quantity",$A$26,"Product_Category",A29) -> 43.359184 | J29: =GETPIVOTDATA("Sum of Total_Cost",$A$26,"Product_Category",A29)/GETPIVOTDATA("Sum of Net_Sales",$A$26,"Product_Category",A29) -> 0.6304264
A30: Storage | B30: 168 | C30: 13179 | D30: 1419.75 | E30: 11759.25 | F30: 7392 | G30: 4367.25 | H30: =GETPIVOTDATA("Sum of Discount_Amt",$A$26,"Product_Category",A30)/GETPIVOTDATA("Sum of Gross_Sales",$A$26,"Product_Category",A30) -> 0.1077282 | I30: =GETPIVOTDATA("Sum of Total_Cost",$A$26,"Product_Category",A30)/GETPIVOTDATA("Sum of Quantity",$A$26,"Product_Category",A30) -> 44 | J30: =GETPIVOTDATA("Sum of Total_Cost",$A$26,"Product_Category",A30)/GETPIVOTDATA("Sum of Net_Sales",$A$26,"Product_Category",A30) -> 0.62861152
A31: Lighting | B31: 145 | C31: 13526 | D31: 1303.25 | E31: 12222.75 | F31: 7519 | G31: 4703.75 | H31: =GETPIVOTDATA("Sum of Discount_Amt",$A$26,"Product_Category",A31)/GETPIVOTDATA("Sum of Gross_Sales",$A$26,"Product_Category",A31) -> 0.096351471 | I31: =GETPIVOTDATA("Sum of Total_Cost",$A$26,"Product_Category",A31)/GETPIVOTDATA("Sum of Quantity",$A$26,"Product_Category",A31) -> 51.855172 | J31: =GETPIVOTDATA("Sum of Total_Cost",$A$26,"Product_Category",A31)/GETPIVOTDATA("Sum of Net_Sales",$A$26,"Product_Category",A31) -> 0.61516435
A32: Grand Total | B32: 1076 | C32: 131457 | D32: 10050.35 | E32: 121406.65 | F32: 78945 | G32: 42461.65
A34: Order_Status | B34: Completed
A35: Monthly Analysis
A36: Row Labels | B36: Net_Sales (£) | C36: Gross_Profit(£)
A37: Jan | B37: 24464.25 | C37: 8740.25
A38: Feb | B38: 18211.5 | C38: 6733.5
A39: Mar | B39: 18350.35 | C39: 6414.35
A40: Apr | B40: 17114.25 | C40: 5545.25
A41: May | B41: 20006.95 | C41: 7057.95
A42: Jun | B42: 23259.35 | C42: 7970.35
A43: Grand Total | B43: 121406.65 | C43: 42461.65
A45: Order_Status | B45: Completed
A47: Sum of Net_Sales | B47: Column Labels
A48: Row Labels | B48: May | C48: Jun | D48: Grand Total
...

Sheet Discount_Analysis
A1: Order_Status | B1: Completed
A2: Discount Analysis
A3: Row Labels | B3: Sum of Gross_Sales | C3: Sum of Discount_Amt | D3: Sum of Net_Sales | E3: Sum of Gross_profit | F3: Discount rate | G3: Gross profit margin
A4: Furniture | B4: 61500 | C4: 4115.25 | D4: 57384.75 | E4: 17888.75 | F4: =GETPIVOTDATA("Sum of Discount_Amt",$A$3,"Product_Category",A4)/GETPIVOTDATA("Sum of Gross_Sales",$A$3,"Product_Category",A4) -> 0.066914634 | G4: =GETPIVOTDATA("Sum of Gross_profit",$A$3,"Product_Category",A4)/GETPIVOTDATA("Sum of Net_Sales",$A$3,"Product_Category",A4) -> 0.31173352
A5: Home Accessories | B5: 24899 | C5: 1709.6 | D5: 23189.4 | E5: 9274.4 | F5: =GETPIVOTDATA("Sum of Discount_Amt",$A$3,"Product_Category",A5)/GETPIVOTDATA("Sum of Gross_Sales",$A$3,"Product_Category",A5) -> 0.068661392 | G5: =GETPIVOTDATA("Sum of Gross_profit",$A$3,"Product_Category",A5)/GETPIVOTDATA("Sum of Net_Sales",$A$3,"Product_Category",A5) -> 0.39994135
A6: Kitchenware | B6: 18353 | C6: 1502.5 | D6: 16850.5 | E6: 6227.5 | F6: =GETPIVOTDATA("Sum of Discount_Amt",$A$3,"Product_Category",A6)/GETPIVOTDATA("Sum of Gross_Sales",$A$3,"Product_Category",A6) -> 0.081866725 | G6: =GETPIVOTDATA("Sum of Gross_profit",$A$3,"Product_Category",A6)/GETPIVOTDATA("Sum of Net_Sales",$A$3,"Product_Category",A6) -> 0.3695736
A7: Lighting | B7: 13526 | C7: 1303.25 | D7: 12222.75 | E7: 4703.75 | F7: =GETPIVOTDATA("Sum of Discount_Amt",$A$3,"Product_Category",A7)/GETPIVOTDATA("Sum of Gross_Sales",$A$3,"Product_Category",A7) -> 0.096351471 | G7: =GETPIVOTDATA("Sum of Gross_profit",$A$3,"Product_Category",A7)/GETPIVOTDATA("Sum of Net_Sales",$A$3,"Product_Category",A7) -> 0.38483565
A8: Storage | B8: 13179 | C8: 1419.75 | D8: 11759.25 | E8: 4367.25 | F8: =GETPIVOTDATA("Sum of Discount_Amt",$A$3,"Product_Category",A8)/GETPIVOTDATA("Sum of Gross_Sales",$A$3,"Product_Category",A8) -> 0.1077282 | G8: =GETPIVOTDATA("Sum of Gross_profit",$A$3,"Product_Category",A8)/GETPIVOTDATA("Sum of Net_Sales",$A$3,"Product_Category",A8) -> 0.37138848
A9: Grand Total | B9: 131457 | C9: 10050.35 | D9: 121406.65 | E9: 42461.65
B12: Product Category | C12: Discount Rate | D12: Gross Profit Margin
B13: =A4 -> Furniture | C13: =F4 -> 0.066914634 | D13: =G4 -> 0.31173352
B14: =A5 -> Home Accessories | C14: =F5 -> 0.068661392 | D14: =G5 -> 0.39994135
B15: =A6 -> Kitchenware | C15: =F6 -> 0.081866725 | D15: =G6 -> 0.3695736
B16: =A7 -> Lighting | C16: =F7 -> 0.096351471 | D16: =G7 -> 0.38483565
B17: =A8 -> Storage | C17: =F8 -> 0.1077282 | D17: =G8 -> 0.37138848

Sheet Dashboard
B2: NORTHSTAR | SALES PERFORMANCE DASHBOARD
B4: JANUARY - JUNE 2026 | Completed Orders
B6: NET SALES | G6: GROSS PROFIT | L6: GROSS PROFIT MARGIN
B7: =GETPIVOTDATA("Sum of Net_Sales",Pivot_Table!$A$15) -> 121406.65 | G7: =GETPIVOTDATA("Sum of Gross_profit",Pivot_Table!$A$15) -> 42461.65 | L7: =G7/B7 -> 0.34974732

Sheet Management Summary
B2: NORTHSTAR HOME & LIVING LTD |SALES PERFORMANCE SUMMARY
B3: Reporting Period: January - June 2026 | Completed Orders Only
B5: Executive Summary:
B6: Northstar Home & Living generated £121,406.65 in Net Sales and £42,461.65 in Gross Profit between January and June 2026, achieving an overall Gross Profit Margin of 34.97%.
B10: West Midlands was the strongest-performing region, while Yorkshire recorded the lowest regional revenue. Furniture generated the highest revenue and gross profit among product categories, although Home Accessories achieved the highest profit margin.
B15: Monthly sales generally declined from January to April before recovering in May and June. Discount analysis showed no consistent relationship between higher category discount rates and lower gross profit margins.
B19: Management Recommendations:
B20: 1. Review Furniture profitability: Examine supplier's costs, pricing and individual product margins to identify opportunities for improving the category's 31.17% gross profit margin.
B23: 2. Improve sales planning: Investigate the January-April sales decline and review historical sales patterns to support better inventory and marketing decisions.
B26: 3. Explore Yorkshire growth opportunities: Identify high-performing products and customer preferences to inform targeted sales and promotional strategies.
B29: Data Limitations:
B30: The analysis covers January to June 2026 and includes only Completed orders. Cancelled and Returned orders were excluded from recognised revenue and profit.
... B36: The six-month reporting period is insufficient to establish long-term trends or seasonality. Further investigation would require additional historical sales and customer data.

Sheet Sales_Data
A1: Order_ID | B1: Order_Date | C1: Region | D1: Sales_Channel | E1: Product_ID | F1: Product_Name | G1: Product_Category | H1: Unit_Price | I1: Quantity | J1: Gross_Sales | K1: Discount_Pct | L1: Discount_Amt | M1: Net_Sales | N1: Unit_Cost | O1: Total_Cost | P1: Gross_profit | Q1: Gross_Pft_Mgn(%) | R1: Order_Status | S1: Sales_Rep
A2: NS-0001 | B2: 46120 | C2: London | D2: Corporate | E2: P103 | F2: =_xlfn.XLOOKUP(E2,Product_Lookup!$A$2:$A$14,Product_Lookup!$B$2:$B$14) -> Desk | G2: =_xlfn.XLOOKUP(Sales_Data!E2,Product_Lookup!$A$2:$A$14,Product_Lookup!$C$2:$C$14) -> Furniture | H2: =_xlfn.XLOOKUP(E2,Product_Lookup!$A$2:$A$14,Product_Lookup!$D$2:$D$14) -> 210 | I2: 3 | J2: =H2*I2 -> 630 | K2: 0.2 | L2: =J2*K2 -> 126 | M2: =J2-L2 -> 504 | N2: =_xlfn.XLOOKUP(E2,Product_Lookup!$A$2:$A$14,Product_Lookup!$E$2:$E$14) -> 132 | O2: =N2*I2 -> 396 | P2: =M2-O2 -> 108 | Q2: =P2/M2 -> 0.21428571 | R2: Completed | S2: Priya
A3: NS-0002 | B3: 46093 | C3: London | D3: Online | E3: P501 | F3: =_xlfn.XLOOKUP(E3,Product_Lookup!$A$2:$A$14,Product_Lookup!$B$2:$B$14) -> Storage Box | G3: =_xlfn.XLOOKUP(Sales_Data!E3,Product_Lookup!$A$2:$A$14,Product_Lookup!$C$2:$C$14) -> Storage | H3: =_xlfn.XLOOKUP(E3,Product_Lookup!$A$2:$A$14,Product_Lookup!$D$2:$D$14) -> 26 | I3: 6 | J3: =H3*I3 -> 156 | K3: 0.15 | L3: =J3*K3 -> 23.4 | M3: =J3-L3 -> 132.6 | N3: =_xlfn.XLOOKUP(E3,Product_Lookup!$A$2:$A$14,Product_Lookup!$E$2:$E$14) -> 11 | O3: =N3*I3 -> 66 | P3: =M3-O3 -> 66.6 | Q3: =P3/M3 -> 0.50226244 | R3: Completed | S3: Zara
A4: NS-0003 | B4: 46027 | C4: London | D4: In-Store | E4: P103 | F4: =_xlfn.XLOOKUP(E4,Product_Lookup!$A$2:$A$14,Product_Lookup!$B$2:$B$14) -> Desk | G4: =_xlfn.XLOOKUP(Sales_Data!E4,Product_Lookup!$A$2:$A$14,Product_Lookup!$C$2:$C$14) -> Furniture | H4: =_xlfn.XLOOKUP(E4,Product_Lookup!$A$2:$A$14,Product_Lookup!$D$2:$D$14) -> 210 | I4: 2 | J4: =H4*I4 -> 420 | K4: 0.25 | L4: =J4*K4 -> 105 | M4: =J4-L4 -> 315 | N4: =_xlfn.XLOOKUP(E4,Product_Lookup!$A$2:$A$14,Product_Lookup!$E$2:$E$14) -> 132 | O4: =N4*I4 -> 264 | P4: =M4-O4 -> 51 | Q4: =P4/M4 -> 0.16190476 | R4: Cancelled | S4: Grace
A5: NS-0004 | B5: 46190 | C5: South East | D5: Online | E5: P401 | F5: =_xlfn.XLOOKUP(E5,Product_Lookup!$A$2:$A$14,Product_Lookup!$B$2:$B$14) -> Table Lamp | G5: =_xlfn.XLOOKUP(Sales_Data!E5,Product_Lookup!$A$2:$A$14,Product_Lookup!$C$2:$C$14) -> Lighting | H5: =_xlfn.XLOOKUP(E5,Product_Lookup!$A$2:$A$14,Product_Lookup!$D$2:$D$14) -> 62 | I5: 4 | J5: =H5*I5 -> 248 | K5: 0 | L5: =J5*K5 -> 0 | M5: =J5-L5 -> 248 | N5: =_xlfn.XLOOKUP(E5,Product_Lookup!$A$2:$A$14,Product_Lookup!$E$2:$E$14) -> 31 | O5: =N5*I5 -> 124 | P5: =M5-O5 -> 124 | Q5: =P5/M5 -> 0.5 | R5: Completed | S5: Zara
A6: NS-0005 | B6: 46095 | C6: South East | D6: In-Store | E6: P201 | F6: =_xlfn.XLOOKUP(E6,Product_Lookup!$A$2:$A$14,Product_Lookup!$B$2:$B$14) -> Kettle | G6: =_xlfn.XLOOKUP(Sales_Data!E6,Product_Lookup!$A$2:$A$14,Product_Lookup!$C$2:$C$14) -> Kitchenware | H6: =_xlfn.XLOOKUP(E6,Product_Lookup!$A$2:$A$14,Product_Lookup!$D$2:$D$14) -> 38 | I6: 2 | J6: =H6*I6 -> 76 | K6: 0 | L6: =J6*K6 -> 0 | M6: =J6-L6 -> 76 | N6: =_xlfn.XLOOKUP(E6,Product_Lookup!$A$2:$A$14,Product_Lookup!$E$2:$E$14) -> 21 | O6: =N6*I6 -> 42 | P6: =M6-O6 -> 34 | Q6: =P6/M6 -> 0.44736842 | R6: Completed | S6: Priya
A7: NS-0006 | B7: 46194 | C7: West Midlands | D7: Online | E7: P102 | F7: =_xlfn.XLOOKUP(E7,Product_Lookup!$A$2:$A$14,Product_Lookup!$B$2:$B$14) -> Dining Chair | G7: =_xlfn.XLOOKUP(Sales_Data!E7,Product_Lookup!$A$2:$A$14,Product_Lookup!$C$2:$C$14) -> Furniture | H7: =_xlfn.XLOOKUP(E7,Product_Lookup!$A$2:$A$14,Product_Lookup!$D$2:$D$14) -> 95 | I7: 1 | J7: =H7*I7 -> 95 | K7: 0.2 | L7: =J7*K7 -> 19 | M7: =J7-L7 -> 76 | N7: =_xlfn.XLOOKUP(E7,Product_Lookup!$A$2:$A$14,Product_Lookup!$E$2:$E$14) -> 54 | O7: =N7*I7 -> 54 | P7: =M7-O7 -> 22 | Q7: =P7/M7 -> 0.28947368 | R7: Completed | S7: Grace
A8: NS-0007 | B8: 46104 | C8: West Midlands | D8: Online | E8: P101 | F8: =_xlfn.XLOOKUP(E8,Product_Lookup!$A$2:$A$14,Product_Lookup!$B$2:$B$14) -> Sofa | G8: =_xlfn.XLOOKUP(Sales_Data!E8,Product_Lookup!$A$2:$A$14,Product_Lookup!$C$2:$C$14) -> Furniture | H8: =_xlfn.XLOOKUP(E8,Product_Lookup!$A$2:$A$14,Product_Lookup!$D$2:$D$14) -> 420 | I8: 3 | J8: =H8*I8 -> 1260 | K8: 0.1 | L8: =J8*K8 -> 126 | M8: =J8-L8 -> 1134 | N8: =_xlfn.XLOOKUP(E8,Product_Lookup!$A$2:$A$14,Product_Lookup!$E$2:$E$14) -> 280 | O8: =N8*I8 -> 840 | P8: =M8-O8 -> 294 | Q8: =P8/M8 -> 0.25925926 | R8: Completed | S8: Lewis
A9: NS-0008 | B9: 46060 | C9: West Midlands | D9: In-Store | E9: P102 | F9: =_xlfn.XLOOKUP(E9,Product_Lookup!$A$2:$A$14,Product_Lookup!$B$2:$B$14) -> Dining Chair | G9: =_xlfn.XLOOKUP(Sales_Data!E9,Product_Lookup!$A$2:$A$14,Product_Lookup!$C$2:$C$14) -> Furniture | H9: =_xlfn.XLOOKUP(E9,Product_Lookup!$A$2:$A$14,Product_Lookup!$D$2:$D$14) -> 95 | I9: 7 | J9: =H9*I9 -> 665 | K9: 0.05 | L9: =J9*K9 -> 33.25 | M9: =J9-L9 -> 631.75 | N9: =_xlfn.XLOOKUP(E9,Product_Lookup!$A$2:$A$14,Product_Lookup!$E$2:$E$14) -> 54 | O9: =N9*I9 -> 378 | P9: =M9-O9 -> 253.75 | Q9: =P9/M9 -> 0.40166205 | R9: Completed | S9: Lewis
A10: NS-0009 | B10: 46081 | C10: West Midlands | D10: In-Store | E10: P103 | F10: =_xlfn.XLOOKUP(E10,Product_Lookup!$A$2:$A$14,Product_Lookup!$B$2:$B$14) -> Desk | G10: =_xlfn.XLOOKUP(Sales_Data!E10,Product_Lookup!$A$2:$A$14,Product_Lookup!$C$2:$C$14) -> Furniture | H10: =_xlfn.XLOOKUP(E10,Product_Lookup!$A$2:$A$14,Product_Lookup!$D$2:$D$14) -> 210 | I10: 4 | J10: =H10*I10 -> 840 | K10: 0 | L10: =J10*K10 -> 0 | M10: =J10-L10 -> 840 | N10: =_xlfn.XLOOKUP(E10,Product_Lookup!$A$2:$A$14,Product_Lookup!$E$2:$E$14) -> 132 | O10: =N10*I10 -> 528 | P10: =M10-O10 -> 312 | Q10: =P10/M10 -> 0.37142857 | R10: Returned | S10: Priya
A11: NS-0010 | B11: 46094 | C11: North West | D11: Online | E11: P101 | F11: =_xlfn.XLOOKUP(E11,Product_Lookup!$A$2:$A$14,Product_Lookup!$B$2:$B$14) -> Sofa | G11: =_xlfn.XLOOKUP(Sales_Data!E11,Product_Lookup!$A$2:$A$14,Product_Lookup!$C$2:$C$14) -> Furniture | H11: =_xlfn.XLOOKUP(E11,Product_Lookup!$A$2:$A$14,Product_Lookup!$D$2:$D$14) -> 420 | I11: 7 | J11: =H11*I11 -> 2940 | K11: 0.1 | L11: =J11*K11 -> 294 | M11: =J11-L11 -> 2646 | N11: =_xlfn.XLOOKUP(E11,Product_Lookup!$A$2:$A$14,Product_Lookup!$E$2:$E$14) -> 280 | O11: =N11*I11 -> 1960 | P11: =M11-O11 -> 686 | Q11: =P11/M11 -> 0.25925926 | R11: Completed | S11: Amira
A12: NS-0011 | B12: 46033 | C12: South East | D12: Online | E12: P402 | F12: =_xlfn.XLOOKUP(E12,Product_Lookup!$A$2:$A$14,Product_Lookup!$B$2:$B$14) -> Floor Lamp | G12: =_xlfn.XLOOKUP(Sales_Data!E12,Product_Lookup!$A$2:$A$14,Product_Lookup!$C$2:$C$14) -> Lighting | H12: =_xlfn.XLOOKUP(E12,Product_Lookup!$A$2:$A$14,Product_Lookup!$D$2:$D$14) -> 125 | I12: 6 | J12: =H12*I12 -> 750 | K12: 0.15 | L12: =J12*K12 -> 112.5 | M12: =J12-L12 -> 637.5 | N12: =_xlfn.XLOOKUP(E12,Product_Lookup!$A$2:$A$14,Product_Lookup!$E$2:$E$14) -> 73 | O12: =N12*I12 -> 438 | P12: =M12-O12 -> 199.5 | Q12: =P12/M12 -> 0.31294118 | R12: Completed | S12: Tom
A13: NS-0012 | B13: 46055 | C13: Yorkshire | D13: Corporate | E13: P301 | F13: =_xlfn.XLOOKUP(E13,Product_Lookup!$A$2:$A$14,Product_Lookup!$B$2:$B$14) -> Cushion Set | G13: =_xlfn.XLOOKUP(Sales_Data!E13,Product_Lookup!$A$2:$A$14,Product_Lookup!$C$2:$C$14) -> Home Accessories | H13: =_xlfn.XLOOKUP(E13,Product_Lookup!$A$2:$A$14,Product_Lookup!$D$2:$D$14) -> 32 | I13: 5 | J13: =H13*I13 -> 160 | K13: 0.1 | L13: =J13*K13 -> 16 | M13: =J13-L13 -> 144 | N13: =_xlfn.XLOOKUP(E13,Product_Lookup!$A$2:$A$14,Product_Lookup!$E$2:$E$14) -> 14 | O13: =N13*I13 -> 70 | P13: =M13-O13 -> 74 | Q13: =P13/M13 -> 0.51388889 | R13: Completed | S13: Lewis
... A289: NS-0288 | B289: 46145 | C289: West Midlands | D289: Corporate | E289: P202 | F289: =_xlfn.XLOOKUP(E289,Product_Lookup!$A$2:$A$14,Product_Lookup!$B$2:$B$14) -> Cookware Set | G289: =_xlfn.XLOOKUP(Sales_Data!E289,Product_Lookup!$A$2:$A$14,Product_Lookup!$C$2:$C$14) -> Kitchenware | H289: =_xlfn.XLOOKUP(E289,Product_Lookup!$A$2:$A$14,Product_Lookup!$D$2:$D$14) -> 110 | I289: 6 | J289: =H289*I289 -> 660 | K289: 0.15 | L289: =J289*K289 -> 99 | M289: =J289-L289 -> 561 | N289: =_xlfn.XLOOKUP(E289,Product_Lookup!$A$2:$A$14,Product_Lookup!$E$2:$E$14) -> 65 | O289: =N289*I289 -> 390 | P289: =M289-O289 -> 171 | Q289: =P289/M289 -> 0.30481283 | R289: Completed | S289: Priya
A290: NS-0289 | B290: 46086 | C290: London | D290: Corporate | E290: P401 | F290: =_xlfn.XLOOKUP(E290,Product_Lookup!$A$2:$A$14,Product_Lookup!$B$2:$B$14) -> Table Lamp | G290: =_xlfn.XLOOKUP(Sales_Data!E290,Product_Lookup!$A$2:$A$14,Product_Lookup!$C$2:$C$14) -> Lighting | H290: =_xlfn.XLOOKUP(E290,Product_Lookup!$A$2:$A$14,Product_Lookup!$D$2:$D$14) -> 62 | I290: 4 | J290: =H290*I290 -> 248 | L290: =J290*K290 -> 0 | M290: =J290-L290 -> 248 | N290: =_xlfn.XLOOKUP(E290,Product_Lookup!$A$2:$A$14,Product_Lookup!$E$2:$E$14) -> 31 | O290: =N290*I290 -> 124 | P290: =M290-O290 -> 124 | Q290: =P290/M290 -> 0.5 | R290: Completed | S290: Priya
A291: NS-0290 | B291: 46194 | C291: London | D291: Corporate | E291: P401 | F291: =_xlfn.XLOOKUP(E291,Product_Lookup!$A$2:$A$14,Product_Lookup!$B$2:$B$14) -> Table Lamp | G291: =_xlfn.XLOOKUP(Sales_Data!E291,Product_Lookup!$A$2:$A$14,Product_Lookup!$C$2:$C$14) -> Lighting | H291: =_xlfn.XLOOKUP(E291,Product_Lookup!$A$2:$A$14,Product_Lookup!$D$2:$D$14) -> 62 | I291: 3 | J291: =H291*I291 -> 186 | K291: 0.05 | L291: =J291*K291 -> 9.3 | M291: =J291-L291 -> 176.7 | N291: =_xlfn.XLOOKUP(E291,Product_Lookup!$A$2:$A$14,Product_Lookup!$E$2:$E$14) -> 31 | O291: =N291*I291 -> 93 | P291: =M291-O291 -> 83.7 | Q291: =P291/M291 -> 0.47368421 | R291: Completed | S291: Priya
A292: NS-0291 | B292: 46085 | C292: London | D292: Online | E292: P303 | F292: =_xlfn.XLOOKUP(E292,Product_Lookup!$A$2:$A$14,Product_Lookup!$B$2:$B$14) -> Rug | G292: =_xlfn.XLOOKUP(Sales_Data!E292,Product_Lookup!$A$2:$A$14,Product_Lookup!$C$2:$C$14) -> Home Accessories | H292: =_xlfn.XLOOKUP(E292,Product_Lookup!$A$2:$A$14,Product_Lookup!$D$2:$D$14) -> 145 | I292: 7 | J292: =H292*I292 -> 1015 | K292: 0.1 | L292: =J292*K292 -> 101.5 | M292: =J292-L292 -> 913.5 | N292: =_xlfn.XLOOKUP(E292,Product_Lookup!$A$2:$A$14,Product_Lookup!$E$2:$E$14) -> 88 | O292: =N292*I292 -> 616 | P292: =M292-O292 -> 297.5 | Q292: =P292/M292 -> 0.3256705 | R292: Completed | S292: Lewis
A293: NS-0292 | B293: 46130 | C293: West Midlands | D293: In-Store | E293: P101 | F293: =_xlfn.XLOOKUP(E293,Product_Lookup!$A$2:$A$14,Product_Lookup!$B$2:$B$14) -> Sofa | G293: =_xlfn.XLOOKUP(Sales_Data!E293,Product_Lookup!$A$2:$A$14,Product_Lookup!$C$2:$C$14) -> Furniture | H293: =_xlfn.XLOOKUP(E293,Product_Lookup!$A$2:$A$14,Product_Lookup!$D$2:$D$14) -> 420 | I293: 1 | J293: =H293*I293 -> 420 | K293: 0.15 | L293: =J293*K293 -> 63 | M293: =J293-L293 -> 357 | N293: =_xlfn.XLOOKUP(E293,Product_Lookup!$A$2:$A$14,Product_Lookup!$E$2:$E$14) -> 280 | O293: =N293*I293 -> 280 | P293: =M293-O293 -> 77 | Q293: =P293/M293 -> 0.21568627 | R293: Completed | S293: Tom
A294: NS-0293 | B294: 46081 | C294: London | D294: Corporate | E294: P302 | F294: =_xlfn.XLOOKUP(E294,Product_Lookup!$A$2:$A$14,Product_Lookup!$B$2:$B$14) -> Wall Mirror | G294: =_xlfn.XLOOKUP(Sales_Data!E294,Product_Lookup!$A$2:$A$14,Product_Lookup!$C$2:$C$14) -> Home Accessories | H294: =_xlfn.XLOOKUP(E294,Product_Lookup!$A$2:$A$14,Product_Lookup!$D$2:$D$14) -> 85 | I294: 7 | J294: =H294*I294 -> 595 | K294: 0.2 | L294: =J294*K294 -> 119 | M294: =J294-L294 -> 476 | N294: =_xlfn.XLOOKUP(E294,Product_Lookup!$A$2:$A$14,Product_Lookup!$E$2:$E$14) -> 41 | O294: =N294*I294 -> 287 | P294: =M294-O294 -> 189 | Q294: =P294/M294 -> 0.39705882 | R294: Returned | S294: Amira
A295: NS-0294 | B295: 46185 | C295: Yorkshire | D295: Corporate | E295: P402 | F295: =_xlfn.XLOOKUP(E295,Product_Lookup!$A$2:$A$14,Product_Lookup!$B$2:$B$14) -> Floor Lamp | G295: =_xlfn.XLOOKUP(Sales_Data!E295,Product_Lookup!$A$2:$A$14,Product_Lookup!$C$2:$C$14) -> Lighting | H295: =_xlfn.XLOOKUP(E295,Product_Lookup!$A$2:$A$14,Product_Lookup!$D$2:$D$14) -> 125 | I295: 4 | J295: =H295*I295 -> 500 | K295: 0.1 | L295: =J295*K295 -> 50 | M295: =J295-L295 -> 450 | N295: =_xlfn.XLOOKUP(E295,Product_Lookup!$A$2:$A$14,Product_Lookup!$E$2:$E$14) -> 73 | O295: =N295*I295 -> 292 | P295: =M295-O295 -> 158 | Q295: =P295/M295 -> 0.35111111 | R295: Completed | S295: Daniel
A296: NS-0295 | B296: 46169 | C296: West Midlands | D296: Online | E296: P202 | F296: =_xlfn.XLOOKUP(E296,Product_Lookup!$A$2:$A$14,Product_Lookup!$B$2:$B$14) -> Cookware Set | G296: =_xlfn.XLOOKUP(Sales_Data!E296,Product_Lookup!$A$2:$A$14,Product_Lookup!$C$2:$C$14) -> Kitchenware | H296: =_xlfn.XLOOKUP(E296,Product_Lookup!$A$2:$A$14,Product_Lookup!$D$2:$D$14) -> 110 | I296: 4 | J296: =H296*I296 -> 440 | K296: 0.1 | L296: =J296*K296 -> 44 | M296: =J296-L296 -> 396 | N296: =_xlfn.XLOOKUP(E296,Product_Lookup!$A$2:$A$14,Product_Lookup!$E$2:$E$14) -> 65 | O296: =N296*I296 -> 260 | P296: =M296-O296 -> 136 | Q296: =P296/M296 -> 0.34343434 | R296: Completed | S296: Lewis
A297: NS-0296 | B297: 46198 | C297: West Midlands | D297: Online | E297: P502 | F297: =_xlfn.XLOOKUP(E297,Product_Lookup!$A$2:$A$14,Product_Lookup!$B$2:$B$14) -> Shelving Unit | G297: =_xlfn.XLOOKUP(Sales_Data!E297,Product_Lookup!$A$2:$A$14,Product_Lookup!$C$2:$C$14) -> Storage | H297: =_xlfn.XLOOKUP(E297,Product_Lookup!$A$2:$A$14,Product_Lookup!$D$2:$D$14) -> 115 | I297: 1 | J297: =H297*I297 -> 115 | K297: 0.25 | L297: =J297*K297 -> 28.75 | M297: =J297-L297 -> 86.25 | N297: =_xlfn.XLOOKUP(E297,Product_Lookup!$A$2:$A$14,Product_Lookup!$E$2:$E$14) -> 67 | O297: =N297*I297 -> 67 | P297: =M297-O297 -> 19.25 | Q297: =P297/M297 -> 0.22318841 | R297: Completed | S297: Amira
A298: NS-0297 | B298: 46032 | C298: West Midlands | D298: In-Store | E298: P202 | F298: =_xlfn.XLOOKUP(E298,Product_Lookup!$A$2:$A$14,Product_Lookup!$B$2:$B$14) -> Cookware Set | G298: =_xlfn.XLOOKUP(Sales_Data!E298,Product_Lookup!$A$2:$A$14,Product_Lookup!$C$2:$C$14) -> Kitchenware | H298: =_xlfn.XLOOKUP(E298,Product_Lookup!$A$2:$A$14,Product_Lookup!$D$2:$D$14) -> 110 | I298: 2 | J298: =H298*I298 -> 220 | K298: 0 | L298: =J298*K298 -> 0 | M298: =J298-L298 -> 220 | N298: =_xlfn.XLOOKUP(E298,Product_Lookup!$A$2:$A$14,Product_Lookup!$E$2:$E$14) -> 65 | O298: =N298*I298 -> 130 | P298: =M298-O298 -> 90 | Q298: =P298/M298 -> 0.40909091 | R298: Completed | S298: Grace
A299: NS-0298 | B299: 46095 | C299: West Midlands | D299: Online | E299: P401 | F299: =_xlfn.XLOOKUP(E299,Product_Lookup!$A$2:$A$14,Product_Lookup!$B$2:$B$14) -> Table Lamp | G299: =_xlfn.XLOOKUP(Sales_Data!E299,Product_Lookup!$A$2:$A$14,Product_Lookup!$C$2:$C$14) -> Lighting | H299: =_xlfn.XLOOKUP(E299,Product_Lookup!$A$2:$A$14,Product_Lookup!$D$2:$D$14) -> 62 | I299: 1 | J299: =H299*I299 -> 62 | K299: 0 | L299: =J299*K299 -> 0 | M299: =J299-L299 -> 62 | N299: =_xlfn.XLOOKUP(E299,Product_Lookup!$A$2:$A$14,Product_Lookup!$E$2:$E$14) -> 31 | O299: =N299*I299 -> 31 | P299: =M299-O299 -> 31 | Q299: =P299/M299 -> 0.5 | R299: Completed | S299: Daniel
A300: NS-0299 | B300: 46183 | C300: London | D300: Corporate | E300: P303 | F300: =_xlfn.XLOOKUP(E300,Product_Lookup!$A$2:$A$14,Product_Lookup!$B$2:$B$14) -> Rug | G300: =_xlfn.XLOOKUP(Sales_Data!E300,Product_Lookup!$A$2:$A$14,Product_Lookup!$C$2:$C$14) -> Home Accessories | H300: =_xlfn.XLOOKUP(E300,Product_Lookup!$A$2:$A$14,Product_Lookup!$D$2:$D$14) -> 145 | I300: 2 | J300: =H300*I300 -> 290 | K300: 0.2 | L300: =J300*K300 -> 58 | M300: =J300-L300 -> 232 | N300: =_xlfn.XLOOKUP(E300,Product_Lookup!$A$2:$A$14,Product_Lookup!$E$2:$E$14) -> 88 | O300: =N300*I300 -> 176 | P300: =M300-O300 -> 56 | Q300: =P300/M300 -> 0.24137931 | R300: Completed | S300: Lewis
A301: NS-0300 | B301: 46183 | C301: West Midlands | D301: In-Store | E301: P303 | F301: =_xlfn.XLOOKUP(E301,Product_Lookup!$A$2:$A$14,Product_Lookup!$B$2:$B$14) -> Rug | G301: =_xlfn.XLOOKUP(Sales_Data!E301,Product_Lookup!$A$2:$A$14,Product_Lookup!$C$2:$C$14) -> Home Accessories | H301: =_xlfn.XLOOKUP(E301,Product_Lookup!$A$2:$A$14,Product_Lookup!$D$2:$D$14) -> 145 | I301: 5 | J301: =H301*I301 -> 725 | K301: 0.2 | L301: =J301*K301 -> 145 | M301: =J301-L301 -> 580 | N301: =_xlfn.XLOOKUP(E301,Product_Lookup!$A$2:$A$14,Product_Lookup!$E$2:$E$14) -> 88 | O301: =N301*I301 -> 440 | P301: =M301-O301 -> 140 | Q301: =P301/M301 -> 0.24137931 | R301: Completed | S301: Amira
A302: NS-0301 | B302: 46069 | C302: London | D302: Corporate | E302: P203 | F302: =_xlfn.XLOOKUP(E302,Product_Lookup!$A$2:$A$14,Product_Lookup!$B$2:$B$14) -> Blender | G302: =_xlfn.XLOOKUP(Sales_Data!E302,Product_Lookup!$A$2:$A$14,Product_Lookup!$C$2:$C$14) -> Kitchenware | H302: =_xlfn.XLOOKUP(E302,Product_Lookup!$A$2:$A$14,Product_Lookup!$D$2:$D$14) -> 75 | I302: 1 | J302: =H302*I302 -> 75 | K302: 0 | L302: =J302*K302 -> 0 | M302: =J302-L302 -> 75 | N302: =_xlfn.XLOOKUP(E302,Product_Lookup!$A$2:$A$14,Product_Lookup!$E$2:$E$14) -> 43 | O302: =N302*I302 -> 43 | P302: =M302-O302 -> 32 | Q302: =P302/M302 -> 0.42666667 | R302: Completed | S302: Priya
... A321: NS-0320 | B321: 46084 | C321: London | D321: In-Store | E321: P203 | F321: =_xlfn.XLOOKUP(E321,Product_Lookup!$A$2:$A$14,Product_Lookup!$B$2:$B$14) -> Blender | G321: =_xlfn.XLOOKUP(Sales_Data!E321,Product_Lookup!$A$2:$A$14,Product_Lookup!$C$2:$C$14) -> Kitchenware | H321: =_xlfn.XLOOKUP(E321,Product_Lookup!$A$2:$A$14,Product_Lookup!$D$2:$D$14) -> 75 | I321: 5 | J321: =H321*I321 -> 375 | K321: 0.2 | L321: =J321*K321 -> 75 | M321: =J321-L321 -> 300 | N321: =_xlfn.XLOOKUP(E321,Product_Lookup!$A$2:$A$14,Product_Lookup!$E$2:$E$14) -> 43 | O321: =N321*I321 -> 215 | P321: =M321-O321 -> 85 | Q321: =P321/M321 -> 0.28333333 | R321: Completed | S321: Grace

Sheet Product_Lookup
A1: Product_ID | B1: Product_Name | C1: Category | D1: Unit_Price_GBP | E1: Unit_Cost_GBP
A2: P101 | B2: Sofa | C2: Furniture | D2: 420 | E2: 280
A3: P102 | B3: Dining Chair | C3: Furniture | D3: 95 | E3: 54
A4: P103 | B4: Desk | C4: Furniture | D4: 210 | E4: 132
A5: P201 | B5: Kettle | C5: Kitchenware | D5: 38 | E5: 21
A6: P202 | B6: Cookware Set | C6: Kitchenware | D6: 110 | E6: 65
A7: P203 | B7: Blender | C7: Kitchenware | D7: 75 | E7: 43
A8: P301 | B8: Cushion Set | C8: Home Accessories | D8: 32 | E8: 14
A9: P302 | B9: Wall Mirror | C9: Home Accessories | D9: 85 | E9: 41
A10: P303 | B10: Rug | C10: Home Accessories | D10: 145 | E10: 88
A11: P401 | B11: Table Lamp | C11: Lighting | D11: 62 | E11: 31
A12: P402 | B12: Floor Lamp | C12: Lighting | D12: 125 | E12: 73
A13: P501 | B13: Storage Box | C13: Storage | D13: 26 | E13: 11
A14: P502 | B14: Shelving Unit | C14: Storage | D14: 115 | E14: 67

Sheet Project_Brief
A1: NORTHSTAR | EXCEL PROJECT 01
A2: Role | B2: Junior Data Analyst
A3: Period | B3: January–June 2026
A4: Business objective | B4: Investigate sales performance, profitability and discounts.
A6: QUESTIONS FROM MANAGEMENT
A7: 1 | B7: How much revenue and profit did we generate?
A8: 2 | B8: Which regions perform best and worst?
A9: 3 | B9: Which categories generate most revenue and profit?
A10: 4 | B10: What is the monthly sales trend?
A11: 5 | B11: How are discounts related to profitability?
A12: 6 | B12: What three actions should management consider?
A14: DELIVERABLES
A15: A | B15: Cleaned, documented transaction data
A16: B | B16: Analysis with calculations and summaries
A17: C | B17: One-page management dashboard
A18: D | B18: Three evidence-based recommendations
A20: BUSINESS RULES
A21: 1 | B21: Use Completed orders for recognised sales and profit.
A22: 2 | B22: Revenue = Quantity × Unit Price × (1 − Discount).
A23: 3 | B23: Cost = Quantity × Unit Cost; Profit = Revenue − Cost.
A24: 4 | B24: Product prices and costs are in Product_Lookup.
A25: 5 | B25: Discounts are stored as percentages (e.g. 0.10 = 10%).
A26: 6 | B26: Returns and cancellations should be investigated, not silently deleted.
A27: 7 | B27: Document any data quality decisions and assumptions.
A29: START HERE
A30: Step 1 | B30: Explore both data sheets and inspect data quality.
A31: Step 2 | B31: Write your own plan before calculating anything.
A32: Step 3 | B32: Send your plan for feedback; then continue independently.
